2019-06-21T16:12:34|CRITICAL|root|Unhandled exception:Traceback (most recent call last):
  File "C:\Users\lindat18\AppData\Local\Continuum\miniconda3\envs\scopefoundry\lib\site-packages\ScopeFoundry\measurement.py", line 25, in run
    self.measurement._thread_run()
  File "C:\Users\lindat18\AppData\Local\Continuum\miniconda3\envs\scopefoundry\lib\site-packages\ScopeFoundry\measurement.py", line 183, in _thread_run
    self.run()
  File "C:\Users\lindat18\Dropbox\Ginger_Lab\Microscope_App\HW_PI_PiezoStage\PiezoStage_independent_movement.py", line 52, in run
    move_here = self.pos_array[i] #get next point for stage to move to
AttributeError: 'PiezoStageIndependentMovement' object has no attribute 'pos_array'

