2019-06-20T11:39:20|CRITICAL|root|Unhandled exception:Traceback (most recent call last):
  File "Microscope_app.py", line 43, in <module>
    app = MicroscopeApp(sys.argv)
  File "C:\Users\lindat18\AppData\Local\Continuum\miniconda3\envs\scopefoundry\lib\site-packages\ScopeFoundry\base_app.py", line 340, in __init__
    self.setup_default_ui()
  File "C:\Users\lindat18\AppData\Local\Continuum\miniconda3\envs\scopefoundry\lib\site-packages\ScopeFoundry\base_app.py", line 380, in setup_default_ui
    measure.setup_figure()
  File "C:\Users\lindat18\Dropbox\Ginger_Lab\Microscope_App\HW_PI_PiezoStage\OceanOptics_Scan.py", line 19, in setup_figure
    self.settings.intg_time.connect(spec_hw.settings.intg_time)
AttributeError: 'LoggedQuantity' object has no attribute 'connect'

