2019-06-20T11:19:42|CRITICAL|root|Unhandled exception:Traceback (most recent call last):
  File "Microscope_app.py", line 43, in <module>
    app = MicroscopeApp(sys.argv)
  File "C:\Users\lindat18\AppData\Local\Continuum\miniconda3\envs\scopefoundry\lib\site-packages\ScopeFoundry\base_app.py", line 340, in __init__
    self.setup_default_ui()
  File "C:\Users\lindat18\AppData\Local\Continuum\miniconda3\envs\scopefoundry\lib\site-packages\ScopeFoundry\base_app.py", line 380, in setup_default_ui
    measure.setup_figure()
  File "C:\Users\lindat18\Dropbox\Ginger_Lab\Microscope_App\HW_PI_PiezoStage\OceanOptics_Scan.py", line 19, in setup_figure
    self.set_details_widget(widget = self.settings.New_UI(include=[spec_hw.settings.intg_time.name, spec_hw.settings.correct_dark_counts.name, "scans_to_avg"]))
  File "C:\Users\lindat18\AppData\Local\Continuum\miniconda3\envs\scopefoundry\lib\site-packages\ScopeFoundry\logged_quantity.py", line 1340, in New_UI
    lq = self.get_lq(lqname)
  File "C:\Users\lindat18\AppData\Local\Continuum\miniconda3\envs\scopefoundry\lib\site-packages\ScopeFoundry\logged_quantity.py", line 1247, in get_lq
    return self._logged_quantities[key]
KeyError: 'intg_time'

