2019-06-21T14:55:07|CRITICAL|root|Unhandled exception:Traceback (most recent call last):
  File "Microscope_app.py", line 56, in <module>
    app = MicroscopeApp(sys.argv)
  File "C:\Users\lindat18\AppData\Local\Continuum\miniconda3\envs\scopefoundry\lib\site-packages\ScopeFoundry\base_app.py", line 340, in __init__
    self.setup_default_ui()
  File "C:\Users\lindat18\AppData\Local\Continuum\miniconda3\envs\scopefoundry\lib\site-packages\ScopeFoundry\base_app.py", line 380, in setup_default_ui
    measure.setup_figure()
  File "C:\Users\lindat18\Dropbox\Ginger_Lab\Microscope_App\HW_PI_PiezoStage\PiezoStage_independent_movement.py", line 20, in setup_figure
    self.ui.import_pushButton.connect(self.open_file)
AttributeError: 'QPushButton' object has no attribute 'connect'

